<sdf version='1.7'>
  <world name='default'>
    <light name='sun' type='directional'>
      <cast_shadows>1</cast_shadows>
      <pose>0 0 10 0 -0 0</pose>
      <diffuse>0.8 0.8 0.8 1</diffuse>
      <specular>0.2 0.2 0.2 1</specular>
      <attenuation>
        <range>1000</range>
        <constant>0.9</constant>
        <linear>0.01</linear>
        <quadratic>0.001</quadratic>
      </attenuation>
      <direction>-0.5 0.1 -0.9</direction>
      <spot>
        <inner_angle>0</inner_angle>
        <outer_angle>0</outer_angle>
        <falloff>0</falloff>
      </spot>
    </light>
    <model name='ground_plane'>
      <static>1</static>
      <link name='link'>
        <collision name='collision'>
          <geometry>
            <plane>
              <normal>0 0 1</normal>
              <size>100 100</size>
            </plane>
          </geometry>
          <surface>
            <friction>
              <ode>
                <mu>100</mu>
                <mu2>50</mu2>
              </ode>
              <torsional>
                <ode/>
              </torsional>
            </friction>
            <contact>
              <ode/>
            </contact>
            <bounce/>
          </surface>
          <max_contacts>10</max_contacts>
        </collision>
        <visual name='visual'>
          <cast_shadows>0</cast_shadows>
          <geometry>
            <plane>
              <normal>0 0 1</normal>
              <size>100 100</size>
            </plane>
          </geometry>
          <material>
            <script>
              <uri>file://media/materials/scripts/gazebo.material</uri>
              <name>Gazebo/Grey</name>
            </script>
          </material>
        </visual>
        <self_collide>0</self_collide>
        <enable_wind>0</enable_wind>
        <kinematic>0</kinematic>
      </link>
    </model>
    <gravity>0 0 -9.8</gravity>
    <magnetic_field>6e-06 2.3e-05 -4.2e-05</magnetic_field>
    <atmosphere type='adiabatic'/>
    <physics type='ode'>
      <max_step_size>0.001</max_step_size>
      <real_time_factor>1</real_time_factor>
      <real_time_update_rate>1000</real_time_update_rate>
    </physics>
    <scene>
      <ambient>0.4 0.4 0.4 1</ambient>
      <background>0.7 0.7 0.7 1</background>
      <shadows>1</shadows>
    </scene>
    <audio>
      <device>default</device>
    </audio>
    <wind/>
    <spherical_coordinates>
      <surface_model>EARTH_WGS84</surface_model>
      <latitude_deg>0</latitude_deg>
      <longitude_deg>0</longitude_deg>
      <elevation>0</elevation>
      <heading_deg>0</heading_deg>
    </spherical_coordinates>
    <model name='Model'>
      <joint name='virtual_joint' type='fixed'>
        <pose relative_to='__model__'>0 0 0 0 -0 0</pose>
        <parent>world</parent>
        <child>base_link</child>
      </joint>
      <link name='base_link'>
        <pose relative_to='virtual_joint'>0 0 0 0 -0 0</pose>
        <inertial>
          <pose>0.000917 -0.050562 0.50877 0 -0 0</pose>
          <mass>215.728</mass>
          <inertia>
            <ixx>34.1786</ixx>
            <ixy>-0.026992</ixy>
            <ixz>0.035376</ixz>
            <iyy>24.0907</iyy>
            <iyz>-1.45857</iyz>
            <izz>26.7821</izz>
          </inertia>
        </inertial>
        <collision name='base_link_collision'>
          <pose>0 0 0 0 -0 0</pose>
          <geometry>
            <mesh>
              <scale>1 1 1</scale>
              <uri>model://ros2_description/meshes/dae/base_linkV02.dae</uri>
            </mesh>
          </geometry>
          <max_contacts>10</max_contacts>
          <surface>
            <contact>
              <ode/>
            </contact>
            <bounce/>
            <friction>
              <torsional>
                <ode/>
              </torsional>
              <ode/>
            </friction>
          </surface>
        </collision>
        <visual name='base_link_visual'>
          <pose>0 0 0 0 -0 0</pose>
          <geometry>
            <mesh>
              <scale>1 1 1</scale>
              <uri>model://ros2_description/meshes/dae/base_linkV02.dae</uri>
            </mesh>
          </geometry>
        </visual>
        <self_collide>0</self_collide>
        <enable_wind>0</enable_wind>
        <kinematic>0</kinematic>
      </link>
      <joint name='Revolute_1' type='revolute'>
        <pose relative_to='base_link'>-0.003488 -0.397366 0.899482 0 -0 0</pose>
        <parent>base_link</parent>
        <child>link_1__1__1</child>
        <axis>
          <xyz>0 0 1</xyz>
          <limit>
            <lower>0</lower>
            <upper>6.28318</upper>
            <effort>100</effort>
            <velocity>100</velocity>
          </limit>
          <dynamics>
            <spring_reference>0</spring_reference>
            <spring_stiffness>0</spring_stiffness>
          </dynamics>
        </axis>
      </joint>
      <link name='link_1__1__1'>
        <pose relative_to='Revolute_1'>0 0 0 0 -0 0</pose>
        <inertial>
          <pose>0.010911 4e-06 0.06352 0 -0 0</pose>
          <mass>12.6229</mass>
          <inertia>
            <ixx>0.027067</ixx>
            <ixy>-1e-06</ixy>
            <ixz>-0.000743</ixz>
            <iyy>0.030809</iyy>
            <iyz>-1e-06</iyz>
            <izz>0.026243</izz>
          </inertia>
        </inertial>
        <collision name='link_1__1__1_collision'>
          <pose>0.003488 0.397366 -0.899482 0 -0 0</pose>
          <geometry>
            <mesh>
              <scale>0.001 0.001 0.001</scale>
              <uri>model://ros2_description/meshes/link_1__1__1.stl</uri>
            </mesh>
          </geometry>
          <max_contacts>10</max_contacts>
          <surface>
            <contact>
              <ode/>
            </contact>
            <bounce/>
            <friction>
              <torsional>
                <ode/>
              </torsional>
              <ode/>
            </friction>
          </surface>
        </collision>
        <visual name='link_1__1__1_visual'>
          <pose>0.003488 0.397366 -0.899482 0 -0 0</pose>
          <geometry>
            <mesh>
              <scale>1 1 1</scale>
              <uri>model://ros2_description/meshes/dae/link_1.dae</uri>
            </mesh>
          </geometry>
        </visual>
        <self_collide>0</self_collide>
        <enable_wind>0</enable_wind>
        <kinematic>0</kinematic>
      </link>
      <joint name='Revolute_2' type='revolute'>
        <pose relative_to='link_1__1__1'>0.0744 0 0.0634 0 -0 0</pose>
        <parent>link_1__1__1</parent>
        <child>link_2__1__1</child>
        <axis>
          <xyz>1 0 0</xyz>
          <limit>
            <lower>0</lower>
            <upper>6.28318</upper>
            <effort>100</effort>
            <velocity>100</velocity>
          </limit>
          <dynamics>
            <spring_reference>0</spring_reference>
            <spring_stiffness>0</spring_stiffness>
          </dynamics>
        </axis>
      </joint>
      <link name='link_2__1__1'>
        <pose relative_to='Revolute_2'>0 0 0 0 -0 0</pose>
        <inertial>
          <pose>0.063478 0 0.2125 0 -0 0</pose>
          <mass>38.2979</mass>
          <inertia>
            <ixx>1.17613</ixx>
            <ixy>0</ixy>
            <ixz>0</ixz>
            <iyy>1.18527</iyy>
            <iyz>-1.7e-05</iyz>
            <izz>0.066964</izz>
          </inertia>
        </inertial>
        <collision name='link_2__1__1_collision'>
          <pose>-0.070912 0.397366 -0.962882 0 -0 0</pose>
          <geometry>
            <mesh>
              <scale>0.001 0.001 0.001</scale>
              <uri>model://ros2_description/meshes/link_2__1__1.stl</uri>
            </mesh>
          </geometry>
          <max_contacts>10</max_contacts>
          <surface>
            <contact>
              <ode/>
            </contact>
            <bounce/>
            <friction>
              <torsional>
                <ode/>
              </torsional>
              <ode/>
            </friction>
          </surface>
        </collision>
        <visual name='link_2__1__1_visual'>
          <pose>-0.070912 0.397366 -0.962882 0 -0 0</pose>
          <geometry>
            <mesh>
              <scale>1 1 1</scale>
              <uri>model://ros2_description/meshes/dae/link_2.dae</uri>
            </mesh>
          </geometry>
        </visual>
        <self_collide>0</self_collide>
        <enable_wind>0</enable_wind>
        <kinematic>0</kinematic>
      </link>
      <joint name='Revolute_3' type='revolute'>
        <pose relative_to='link_2__1__1'>0 0 0.425 0 -0 0</pose>
        <parent>link_2__1__1</parent>
        <child>link_3__1__1</child>
        <axis>
          <xyz>-1 0 0</xyz>
          <limit>
            <lower>-5.23599</lower>
            <upper>0</upper>
            <effort>100</effort>
            <velocity>100</velocity>
          </limit>
          <dynamics>
            <spring_reference>0</spring_reference>
            <spring_stiffness>0</spring_stiffness>
          </dynamics>
        </axis>
      </joint>
      <link name='link_3__1__1'>
        <pose relative_to='Revolute_3'>0 0 0 0 -0 0</pose>
        <inertial>
          <pose>-0.061112 0.071394 -0.1531 0 -0 0</pose>
          <mass>21.7937</mass>
          <inertia>
            <ixx>0.480772</ixx>
            <ixy>0.013209</ixy>
            <ixz>-0.028324</ixz>
            <iyy>0.403523</iyy>
            <iyz>0.175801</iyz>
            <izz>0.10852</izz>
          </inertia>
        </inertial>
        <collision name='link_3__1__1_collision'>
          <pose>-0.070912 0.397366 -1.38788 0 -0 0</pose>
          <geometry>
            <mesh>
              <scale>0.001 0.001 0.001</scale>
              <uri>model://ros2_description/meshes/link_3__1__1.stl</uri>
            </mesh>
          </geometry>
          <max_contacts>10</max_contacts>
          <surface>
            <contact>
              <ode/>
            </contact>
            <bounce/>
            <friction>
              <torsional>
                <ode/>
              </torsional>
              <ode/>
            </friction>
          </surface>
        </collision>
        <visual name='link_3__1__1_visual'>
          <pose>-0.070912 0.397366 -1.38788 0 -0 0</pose>
          <geometry>
            <mesh>
              <scale>1 1 1</scale>
              <uri>model://ros2_description/meshes/dae/link_3.dae</uri>
            </mesh>
          </geometry>
        </visual>
        <self_collide>0</self_collide>
        <enable_wind>0</enable_wind>
        <kinematic>0</kinematic>
      </link>
      <joint name='Revolute_4' type='revolute'>
        <pose relative_to='link_3__1__1'>-0.0215 0.165751 -0.355454 0 -0 0</pose>
        <parent>link_3__1__1</parent>
        <child>link_4__1__1</child>
        <axis>
          <xyz>1 0 0</xyz>
          <limit>
            <lower>-6.28318</lower>
            <upper>0</upper>
            <effort>100</effort>
            <velocity>100</velocity>
          </limit>
          <dynamics>
            <spring_reference>0</spring_reference>
            <spring_stiffness>0</spring_stiffness>
          </dynamics>
        </axis>
      </joint>
      <link name='link_4__1__1'>
        <pose relative_to='Revolute_4'>0 0 0 0 -0 0</pose>
        <inertial>
          <pose>0.062077 -0.002502 0.000662 0 -0 0</pose>
          <mass>5.16296</mass>
          <inertia>
            <ixx>0.005384</ixx>
            <ixy>0.000197</ixy>
            <ixz>-5.1e-05</ixz>
            <iyy>0.007049</iyy>
            <iyz>0.000406</iyz>
            <izz>0.00846</izz>
          </inertia>
        </inertial>
        <collision name='link_4__1__1_collision'>
          <pose>-0.049412 0.231615 -1.03243 0 -0 0</pose>
          <geometry>
            <mesh>
              <scale>0.001 0.001 0.001</scale>
              <uri>model://ros2_description/meshes/link_4__1__1.stl</uri>
            </mesh>
          </geometry>
          <max_contacts>10</max_contacts>
          <surface>
            <contact>
              <ode/>
            </contact>
            <bounce/>
            <friction>
              <torsional>
                <ode/>
              </torsional>
              <ode/>
            </friction>
          </surface>
        </collision>
        <visual name='link_4__1__1_visual'>
          <pose>-0.049412 0.231615 -1.03243 0 -0 0</pose>
          <geometry>
            <mesh>
              <scale>0.001 0.001 0.001</scale>
              <uri>model://ros2_description/meshes/link_4__1__1.stl</uri>
            </mesh>
          </geometry>
        </visual>
        <self_collide>0</self_collide>
        <enable_wind>0</enable_wind>
        <kinematic>0</kinematic>
      </link>
      <joint name='Revolute_5' type='revolute'>
        <pose relative_to='link_4__1__1'>0.0804 0.044723 -0.011983 0 -0 0</pose>
        <parent>link_4__1__1</parent>
        <child>link_5__1__1</child>
        <axis>
          <xyz>0 0.965926 -0.258819</xyz>
          <limit>
            <lower>0</lower>
            <upper>6.28318</upper>
            <effort>100</effort>
            <velocity>100</velocity>
          </limit>
          <dynamics>
            <spring_reference>0</spring_reference>
            <spring_stiffness>0</spring_stiffness>
          </dynamics>
        </axis>
      </joint>
      <link name='link_5__1__1'>
        <pose relative_to='Revolute_5'>0 0 0 0 -0 0</pose>
        <inertial>
          <pose>9e-06 0.045356 -0.008065 0 -0 0</pose>
          <mass>4.25201</mass>
          <inertia>
            <ixx>0.005555</ixx>
            <ixy>-2e-06</ixy>
            <ixz>0</ixz>
            <iyy>0.004691</iyy>
            <iyz>-0.000303</iyz>
            <izz>0.00398</izz>
          </inertia>
        </inertial>
        <collision name='link_5__1__1_collision'>
          <pose>-0.129812 0.186892 -1.02045 0 -0 0</pose>
          <geometry>
            <mesh>
              <scale>0.001 0.001 0.001</scale>
              <uri>model://ros2_description/meshes/link_5__1__1.stl</uri>
            </mesh>
          </geometry>
          <max_contacts>10</max_contacts>
          <surface>
            <contact>
              <ode/>
            </contact>
            <bounce/>
            <friction>
              <torsional>
                <ode/>
              </torsional>
              <ode/>
            </friction>
          </surface>
        </collision>
        <visual name='link_5__1__1_visual'>
          <pose>-0.129812 0.186892 -1.02045 0 -0 0</pose>
          <geometry>
            <mesh>
              <scale>1 1 1</scale>
              <uri>model://ros2_description/meshes/dae/link_5.dae</uri>
            </mesh>
          </geometry>
        </visual>
        <self_collide>0</self_collide>
        <enable_wind>0</enable_wind>
        <kinematic>0</kinematic>
      </link>
      <joint name='Revolute_6' type='revolute'>
        <pose relative_to='link_5__1__1'>0 0.039752 -0.057964 0 -0 0</pose>
        <parent>link_5__1__1</parent>
        <child>link_6__1__1</child>
        <axis>
          <xyz>0 -0.258819 -0.965926</xyz>
          <limit>
            <lower>0</lower>
            <upper>6.28318</upper>
            <effort>100</effort>
            <velocity>100</velocity>
          </limit>
          <dynamics>
            <spring_reference>0</spring_reference>
            <spring_stiffness>0</spring_stiffness>
          </dynamics>
        </axis>
      </joint>
      <link name='link_6__1__1'>
        <pose relative_to='Revolute_6'>0 0 0 0 -0 0</pose>
        <inertial>
          <pose>-0.000553 0.012295 -0.065238 0 -0 0</pose>
          <mass>4.35397</mass>
          <inertia>
            <ixx>0.0103396</ixx>
            <ixy>6.4694e-05</ixy>
            <ixz>-7.13997e-05</ixz>
            <iyy>0.00920455</iyy>
            <iyz>0.00240999</iyz>
            <izz>0.00689185</izz>
          </inertia>
        </inertial>
        <collision name='link_6__1__1_collision'>
          <pose>-0.129812 0.14714 -0.962481 0 -0 0</pose>
          <geometry>
            <mesh>
              <scale>0.001 0.001 0.001</scale>
              <uri>model://ros2_description/meshes/link_6__1__1.stl</uri>
            </mesh>
          </geometry>
          <max_contacts>10</max_contacts>
          <surface>
            <contact>
              <ode/>
            </contact>
            <bounce/>
            <friction>
              <torsional>
                <ode/>
              </torsional>
              <ode/>
            </friction>
          </surface>
        </collision>
        <collision name='link_6__1__1_fixed_joint_lump__gripper_1_collision_1'>
          <pose>-0.129812 0.14714 -0.962481 0 -0 0</pose>
          <geometry>
            <mesh>
              <scale>0.001 0.001 0.001</scale>
              <uri>model://ros2_description/meshes/gripper_1.stl</uri>
            </mesh>
          </geometry>
          <max_contacts>10</max_contacts>
          <surface>
            <contact>
              <ode/>
            </contact>
            <bounce/>
            <friction>
              <torsional>
                <ode/>
              </torsional>
              <ode/>
            </friction>
          </surface>
        </collision>
        <collision name='link_6__1__1_fixed_joint_lump__femto_base_link_collision_2'>
          <pose>-0.129812 0.14714 -0.962481 0 -0 0</pose>
          <geometry>
            <mesh>
              <scale>0.001 0.001 0.001</scale>
              <uri>model://ros2_description/meshes/Femto_bolt_v1_1.stl</uri>
            </mesh>
          </geometry>
          <max_contacts>10</max_contacts>
          <surface>
            <contact>
              <ode/>
            </contact>
            <bounce/>
            <friction>
              <torsional>
                <ode/>
              </torsional>
              <ode/>
            </friction>
          </surface>
        </collision>
        <visual name='link_6__1__1_visual'>
          <pose>-0.129812 0.14714 -0.962481 0 -0 0</pose>
          <geometry>
            <mesh>
              <scale>0.001 0.001 0.001</scale>
              <uri>model://ros2_description/meshes/link_6__1__1.stl</uri>
            </mesh>
          </geometry>
        </visual>
        <visual name='link_6__1__1_fixed_joint_lump__gripper_1_visual_1'>
          <pose>-0.129812 0.14714 -0.962481 0 -0 0</pose>
          <geometry>
            <mesh>
              <scale>0.001 0.001 0.001</scale>
              <uri>model://ros2_description/meshes/gripper_1.stl</uri>
            </mesh>
          </geometry>
        </visual>
        <visual name='link_6__1__1_fixed_joint_lump__femto_base_link_visual_2'>
          <pose>-0.129812 0.14714 -0.962481 0 -0 0</pose>
          <geometry>
            <mesh>
              <scale>0.001 0.001 0.001</scale>
              <uri>model://ros2_description/meshes/Femto_bolt_v1_1.stl</uri>
            </mesh>
          </geometry>
        </visual>
        <sensor name='femto' type='depth'>
          <visualize>1</visualize>
          <update_rate>30</update_rate>
          <camera>
            <horizontal_fov>2.0944</horizontal_fov>
            <image>
              <format>B8G8R8</format>
              <width>512</width>
              <height>512</height>
            </image>
            <clip>
              <near>0.25</near>
              <far>2.21</far>
            </clip>
          </camera>
          <plugin name='femto_link_controller' filename='libgazebo_ros_camera.so'>
            <frame_name>femto_link_optical</frame_name>
            <min_depth>0.25</min_depth>
            <max_depth>2.21</max_depth>
          </plugin>
          <pose>-0.003225 0.030012 -0.127188 -3.14159 1.309 -1.5708</pose>
        </sensor>
        <self_collide>0</self_collide>
        <enable_wind>0</enable_wind>
        <kinematic>0</kinematic>
      </link>
      <static>0</static>
      <plugin name='gazebo_ros2_control' filename='libgazebo_ros2_control.so'>
        <robot_param>robot_description</robot_param>
        <robot_param_node>robot_state_publisher</robot_param_node>
        <parameters>/home/administrator/ros2_workshop_manipal/install/ros2_description/share/ros2_description/config/medi_assist_config.yaml</parameters>
      </plugin>
      <pose>0 0 0 0 -0 0</pose>
    </model>
    <model name='medical_scalp'>
      <static>0</static>
      <link name='link'>
        <gravity>1</gravity>
        <self_collide>0</self_collide>
        <inertial>
          <mass>0.08</mass>
          <inertia>
            <ixx>3e-05</ixx>
            <iyy>0.0003</iyy>
            <izz>0.0003</izz>
            <ixy>0</ixy>
            <ixz>0</ixz>
            <iyz>0</iyz>
          </inertia>
          <pose>0 0 0 0 -0 0</pose>
        </inertial>
        <visual name='visual'>
          <geometry>
            <mesh>
              <uri>model://medical_scalp/meshes/scaple_fusion360.stl</uri>
              <scale>1 1 1</scale>
            </mesh>
          </geometry>
          <cast_shadows>0</cast_shadows>
        </visual>
        <collision name='collision'>
          <pose>0 0 0 0 -0 1.5708</pose>
          <geometry>
            <box>
              <size>0.2 0.07 0.035</size>
            </box>
          </geometry>
          <surface>
            <contact>
              <ode/>
            </contact>
            <friction>
              <ode/>
              <torsional>
                <ode/>
              </torsional>
            </friction>
            <bounce/>
          </surface>
          <max_contacts>10</max_contacts>
        </collision>
        <enable_wind>0</enable_wind>
        <kinematic>0</kinematic>
      </link>
      <pose>-0.316625 0.744369 0 0 -0 0</pose>
    </model>
    <model name='medical_scalp_clone'>
      <static>0</static>
      <link name='link'>
        <gravity>1</gravity>
        <self_collide>0</self_collide>
        <inertial>
          <mass>0.08</mass>
          <inertia>
            <ixx>3e-05</ixx>
            <iyy>0.0003</iyy>
            <izz>0.0003</izz>
            <ixy>0</ixy>
            <ixz>0</ixz>
            <iyz>0</iyz>
          </inertia>
          <pose>0 0 0 0 -0 0</pose>
        </inertial>
        <visual name='visual'>
          <geometry>
            <mesh>
              <uri>model://medical_scalp/meshes/scaple_fusion360.stl</uri>
              <scale>1 1 1</scale>
            </mesh>
          </geometry>
          <cast_shadows>0</cast_shadows>
        </visual>
        <collision name='collision'>
          <pose>0 0 0 0 -0 1.5708</pose>
          <geometry>
            <box>
              <size>0.2 0.07 0.035</size>
            </box>
          </geometry>
          <surface>
            <contact>
              <ode/>
            </contact>
            <friction>
              <ode/>
              <torsional>
                <ode/>
              </torsional>
            </friction>
            <bounce/>
          </surface>
          <max_contacts>10</max_contacts>
        </collision>
        <enable_wind>0</enable_wind>
        <kinematic>0</kinematic>
      </link>
      <pose>0.149059 0.126307 0.823481 -2e-05 -1.2e-05 -0.007864</pose>
    </model>
    <model name='medical_scissors'>
      <static>0</static>
      <link name='link'>
        <gravity>1</gravity>
        <self_collide>0</self_collide>
        <inertial>
          <mass>0.08</mass>
          <inertia>
            <ixx>3e-05</ixx>
            <iyy>0.0003</iyy>
            <izz>0.0003</izz>
            <ixy>0</ixy>
            <ixz>0</ixz>
            <iyz>0</iyz>
          </inertia>
          <pose>0 0 0 0 -0 0</pose>
        </inertial>
        <visual name='visual'>
          <geometry>
            <mesh>
              <uri>model://medical_scissors/meshes/scissors_fusion360.stl</uri>
              <scale>1 1 1</scale>
            </mesh>
          </geometry>
          <cast_shadows>0</cast_shadows>
        </visual>
        <collision name='collision'>
          <pose>0 0 0 0 -0 1.5708</pose>
          <geometry>
            <box>
              <size>0.2 0.07 0.035</size>
            </box>
          </geometry>
          <surface>
            <contact>
              <ode/>
            </contact>
            <friction>
              <ode/>
              <torsional>
                <ode/>
              </torsional>
            </friction>
            <bounce/>
          </surface>
          <max_contacts>10</max_contacts>
        </collision>
        <enable_wind>0</enable_wind>
        <kinematic>0</kinematic>
      </link>
      <pose>-0.586407 0.975671 0 0 -0 0</pose>
    </model>
    <model name='medical_scissors_clone'>
      <static>0</static>
      <link name='link'>
        <gravity>1</gravity>
        <self_collide>0</self_collide>
        <inertial>
          <mass>0.08</mass>
          <inertia>
            <ixx>3e-05</ixx>
            <iyy>0.0003</iyy>
            <izz>0.0003</izz>
            <ixy>0</ixy>
            <ixz>0</ixz>
            <iyz>0</iyz>
          </inertia>
          <pose>0 0 0 0 -0 0</pose>
        </inertial>
        <visual name='visual'>
          <geometry>
            <mesh>
              <uri>model://medical_scissors/meshes/scissors_fusion360.stl</uri>
              <scale>1 1 1</scale>
            </mesh>
          </geometry>
          <cast_shadows>0</cast_shadows>
        </visual>
        <collision name='collision'>
          <pose>0 0 0 0 -0 1.5708</pose>
          <geometry>
            <box>
              <size>0.2 0.07 0.035</size>
            </box>
          </geometry>
          <surface>
            <contact>
              <ode/>
            </contact>
            <friction>
              <ode/>
              <torsional>
                <ode/>
              </torsional>
            </friction>
            <bounce/>
          </surface>
          <max_contacts>10</max_contacts>
        </collision>
        <enable_wind>0</enable_wind>
        <kinematic>0</kinematic>
      </link>
      <pose>-0.011209 0.102604 0.823485 -6.2e-05 -3.2e-05 -0.000863</pose>
    </model>
    <gui fullscreen='0'>
      <camera name='user_camera'>
        <pose>2.23816 1.08945 2.67179 0 0.543641 -2.84297</pose>
        <view_controller>orbit</view_controller>
        <projection_type>perspective</projection_type>
      </camera>
    </gui>
  </world>
</sdf>
